
2021-07-22 15:25:10,874 django.utils.autoreload INFO     Watching for file changes with StatReloader
2021-07-22 15:25:46,883 django.utils.autoreload INFO     Watching for file changes with StatReloader
2021-07-22 15:27:59,664 django.utils.autoreload INFO     Watching for file changes with StatReloader
2021-07-22 15:28:47,660 django.request WARNING  Not Found: /internal/create/
2021-07-22 15:29:02,941 django.request WARNING  Not Found: /internal/
2021-07-22 15:39:24,300 django.utils.autoreload INFO     C:\Users\YOGA\Documents\richasdy\xd\internal\admin.py changed, reloading.
2021-07-22 15:39:25,391 django.utils.autoreload INFO     Watching for file changes with StatReloader
2021-07-22 15:39:37,684 django.utils.autoreload INFO     C:\Users\YOGA\Documents\richasdy\xd\internal\admin.py changed, reloading.
2021-07-22 15:39:38,707 django.utils.autoreload INFO     Watching for file changes with StatReloader
2021-07-22 15:41:03,022 django.utils.autoreload INFO     C:\Users\YOGA\Documents\richasdy\xd\internal\models.py changed, reloading.
2021-07-22 15:41:04,129 django.utils.autoreload INFO     Watching for file changes with StatReloader
2021-07-22 15:41:59,550 django.utils.autoreload INFO     C:\Users\YOGA\Documents\richasdy\xd\internal\urls.py changed, reloading.
2021-07-22 15:42:01,252 django.utils.autoreload INFO     Watching for file changes with StatReloader
2021-07-22 15:42:13,066 django.utils.autoreload INFO     C:\Users\YOGA\Documents\richasdy\xd\internal\urls.py changed, reloading.
2021-07-22 15:42:14,741 django.utils.autoreload INFO     Watching for file changes with StatReloader
2021-07-22 15:43:06,355 django.utils.autoreload INFO     C:\Users\YOGA\Documents\richasdy\xd\internal\views.py changed, reloading.
2021-07-22 15:43:07,569 django.utils.autoreload INFO     Watching for file changes with StatReloader
2021-07-22 15:43:22,066 django.utils.autoreload INFO     C:\Users\YOGA\Documents\richasdy\xd\internal\views.py changed, reloading.
2021-07-22 15:43:23,233 django.utils.autoreload INFO     Watching for file changes with StatReloader
2021-07-22 15:46:06,727 django.utils.autoreload INFO     C:\Users\YOGA\Documents\richasdy\xd\internal\urls.py changed, reloading.
2021-07-22 15:46:07,789 django.utils.autoreload INFO     Watching for file changes with StatReloader
2021-07-22 15:46:40,882 django.utils.autoreload INFO     Watching for file changes with StatReloader
2021-07-22 15:47:05,563 django.request ERROR    Internal Server Error: /internal/create/
Traceback (most recent call last):
  File "C:\Users\YOGA\AppData\Local\Programs\Python\Python39\lib\site-packages\django\core\handlers\exception.py", line 47, in inner
    response = get_response(request)
  File "C:\Users\YOGA\AppData\Local\Programs\Python\Python39\lib\site-packages\django\core\handlers\base.py", line 181, in _get_response
    response = wrapped_callback(request, *callback_args, **callback_kwargs)
  File "C:\Users\YOGA\Documents\richasdy\xd\internal\views.py", line 127, in create
    return HttpResponseRedirect("/internal/form/")
NameError: name 'HttpResponseRedirect' is not defined
2021-07-22 15:47:49,426 django.utils.autoreload INFO     C:\Users\YOGA\Documents\richasdy\xd\internal\views.py changed, reloading.
2021-07-22 15:47:50,515 django.utils.autoreload INFO     Watching for file changes with StatReloader
2021-07-22 15:47:50,990 django.request ERROR    Internal Server Error: /internal/create/
Traceback (most recent call last):
  File "C:\Users\YOGA\AppData\Local\Programs\Python\Python39\lib\site-packages\django\core\handlers\exception.py", line 47, in inner
    response = get_response(request)
  File "C:\Users\YOGA\AppData\Local\Programs\Python\Python39\lib\site-packages\django\core\handlers\base.py", line 181, in _get_response
    response = wrapped_callback(request, *callback_args, **callback_kwargs)
  File "C:\Users\YOGA\Documents\richasdy\xd\internal\views.py", line 127, in create
    return HttpResponseRedirect("/form/")
NameError: name 'HttpResponseRedirect' is not defined
2021-07-22 15:48:21,187 django.utils.autoreload INFO     C:\Users\YOGA\Documents\richasdy\xd\internal\views.py changed, reloading.
2021-07-22 15:48:22,368 django.utils.autoreload INFO     Watching for file changes with StatReloader
2021-07-22 15:48:26,182 django.request WARNING  Not Found: /form/
2021-07-22 15:48:38,146 django.request ERROR    Internal Server Error: /internal/form/
Traceback (most recent call last):
  File "C:\Users\YOGA\AppData\Local\Programs\Python\Python39\lib\site-packages\django\core\handlers\exception.py", line 47, in inner
    response = get_response(request)
  File "C:\Users\YOGA\AppData\Local\Programs\Python\Python39\lib\site-packages\django\core\handlers\base.py", line 181, in _get_response
    response = wrapped_callback(request, *callback_args, **callback_kwargs)
  File "C:\Users\YOGA\Documents\richasdy\xd\internal\views.py", line 116, in form
    return render(request, 'form.html', context)
  File "C:\Users\YOGA\AppData\Local\Programs\Python\Python39\lib\site-packages\django\shortcuts.py", line 19, in render
    content = loader.render_to_string(template_name, context, request, using=using)
  File "C:\Users\YOGA\AppData\Local\Programs\Python\Python39\lib\site-packages\django\template\loader.py", line 61, in render_to_string
    template = get_template(template_name, using=using)
  File "C:\Users\YOGA\AppData\Local\Programs\Python\Python39\lib\site-packages\django\template\loader.py", line 19, in get_template
    raise TemplateDoesNotExist(template_name, chain=chain)
django.template.exceptions.TemplateDoesNotExist: form.html
2021-07-22 15:48:43,839 django.request WARNING  Not Found: /internal/
2021-07-22 15:49:04,592 django.utils.autoreload INFO     C:\Users\YOGA\Documents\richasdy\xd\internal\views.py changed, reloading.
2021-07-22 15:49:05,681 django.utils.autoreload INFO     Watching for file changes with StatReloader
2021-07-22 15:49:06,062 django.request WARNING  Not Found: /internal/
2021-07-22 15:49:40,573 django.request WARNING  Not Found: /internal/create/internal/form/
2021-07-22 15:50:07,706 django.utils.autoreload INFO     C:\Users\YOGA\Documents\richasdy\xd\internal\views.py changed, reloading.
2021-07-22 15:50:08,687 django.utils.autoreload INFO     Watching for file changes with StatReloader
2021-07-22 15:50:13,406 django.request WARNING  Not Found: /internal/create/internal/create
2021-07-22 15:50:30,824 django.request WARNING  Not Found: /form/
2021-07-22 15:50:41,998 django.utils.autoreload INFO     C:\Users\YOGA\Documents\richasdy\xd\internal\views.py changed, reloading.
2021-07-22 15:50:43,144 django.utils.autoreload INFO     Watching for file changes with StatReloader
2021-07-22 15:51:02,926 django.utils.autoreload INFO     C:\Users\YOGA\Documents\richasdy\xd\internal\views.py changed, reloading.
2021-07-22 15:51:03,978 django.utils.autoreload INFO     Watching for file changes with StatReloader
2021-07-22 15:51:04,404 django.request WARNING  Not Found: /form/
2021-07-22 15:51:11,521 django.request ERROR    Internal Server Error: /internal/form/
Traceback (most recent call last):
  File "C:\Users\YOGA\AppData\Local\Programs\Python\Python39\lib\site-packages\django\core\handlers\exception.py", line 47, in inner
    response = get_response(request)
  File "C:\Users\YOGA\AppData\Local\Programs\Python\Python39\lib\site-packages\django\core\handlers\base.py", line 181, in _get_response
    response = wrapped_callback(request, *callback_args, **callback_kwargs)
  File "C:\Users\YOGA\Documents\richasdy\xd\internal\views.py", line 116, in form
    return render(request, '/form.html', context)
  File "C:\Users\YOGA\AppData\Local\Programs\Python\Python39\lib\site-packages\django\shortcuts.py", line 19, in render
    content = loader.render_to_string(template_name, context, request, using=using)
  File "C:\Users\YOGA\AppData\Local\Programs\Python\Python39\lib\site-packages\django\template\loader.py", line 61, in render_to_string
    template = get_template(template_name, using=using)
  File "C:\Users\YOGA\AppData\Local\Programs\Python\Python39\lib\site-packages\django\template\loader.py", line 19, in get_template
    raise TemplateDoesNotExist(template_name, chain=chain)
django.template.exceptions.TemplateDoesNotExist: /form.html
2021-07-22 15:51:29,140 django.utils.autoreload INFO     C:\Users\YOGA\Documents\richasdy\xd\internal\views.py changed, reloading.
2021-07-22 15:51:30,185 django.utils.autoreload INFO     Watching for file changes with StatReloader
2021-07-22 15:51:52,992 django.request WARNING  Not Found: /internal/create/internal/form/
2021-07-22 17:08:18,489 django.utils.autoreload INFO     C:\Users\YOGA\Documents\richasdy\xd\internal\views.py changed, reloading.
2021-07-22 17:08:19,671 django.utils.autoreload INFO     Watching for file changes with StatReloader
2021-07-22 17:08:56,776 django.utils.autoreload INFO     C:\Users\YOGA\Documents\richasdy\xd\internal\views.py changed, reloading.
2021-07-22 17:08:57,965 django.utils.autoreload INFO     Watching for file changes with StatReloader
2021-07-22 17:33:04,838 django.request WARNING  Not Found: /internal/create/{% static '/vendors/moment/min/moment.min.js
2021-07-22 17:33:05,478 django.request WARNING  Not Found: /internal/create/{% static '/components/core/img/avatars/avatar-2.png' }
2021-07-22 17:33:05,635 django.request WARNING  Not Found: /internal/create/{% static '/vendors/moment/min/moment.min.js
2021-07-22 17:39:56,562 django.request WARNING  Not Found: /internal/create/{% static 'external/vendors/moment/min/moment.min.js
2021-07-22 17:39:57,092 django.request WARNING  Not Found: /internal/create/{% static 'external/vendors/moment/min/moment.min.js
2021-07-22 17:39:57,100 django.request WARNING  Not Found: /internal/create/{% static 'external/components/core/img/avatars/avatar-2.png' }
2021-07-22 17:40:11,390 external.views INFO     loading portal berita view
2021-07-22 17:40:17,463 external.views INFO     loading twitter view
2021-07-22 18:06:36,410 django.request ERROR    Internal Server Error: /internal/create/
Traceback (most recent call last):
  File "C:\Users\YOGA\AppData\Local\Programs\Python\Python39\lib\site-packages\django\db\backends\utils.py", line 84, in _execute
    return self.cursor.execute(sql, params)
  File "C:\Users\YOGA\AppData\Local\Programs\Python\Python39\lib\site-packages\django\db\backends\sqlite3\base.py", line 423, in execute
    return Database.Cursor.execute(self, query, params)
sqlite3.IntegrityError: NOT NULL constraint failed: internal_tablemodel.username

The above exception was the direct cause of the following exception:

Traceback (most recent call last):
  File "C:\Users\YOGA\AppData\Local\Programs\Python\Python39\lib\site-packages\django\core\handlers\exception.py", line 47, in inner
    response = get_response(request)
  File "C:\Users\YOGA\AppData\Local\Programs\Python\Python39\lib\site-packages\django\core\handlers\base.py", line 181, in _get_response
    response = wrapped_callback(request, *callback_args, **callback_kwargs)
  File "C:\Users\YOGA\Documents\richasdy\xd\internal\views.py", line 122, in create
    TableModel.objects.create(
  File "C:\Users\YOGA\AppData\Local\Programs\Python\Python39\lib\site-packages\django\db\models\manager.py", line 85, in manager_method
    return getattr(self.get_queryset(), name)(*args, **kwargs)
  File "C:\Users\YOGA\AppData\Local\Programs\Python\Python39\lib\site-packages\django\db\models\query.py", line 453, in create
    obj.save(force_insert=True, using=self.db)
  File "C:\Users\YOGA\AppData\Local\Programs\Python\Python39\lib\site-packages\django\db\models\base.py", line 726, in save
    self.save_base(using=using, force_insert=force_insert,
  File "C:\Users\YOGA\AppData\Local\Programs\Python\Python39\lib\site-packages\django\db\models\base.py", line 763, in save_base
    updated = self._save_table(
  File "C:\Users\YOGA\AppData\Local\Programs\Python\Python39\lib\site-packages\django\db\models\base.py", line 868, in _save_table
    results = self._do_insert(cls._base_manager, using, fields, returning_fields, raw)
  File "C:\Users\YOGA\AppData\Local\Programs\Python\Python39\lib\site-packages\django\db\models\base.py", line 906, in _do_insert
    return manager._insert(
  File "C:\Users\YOGA\AppData\Local\Programs\Python\Python39\lib\site-packages\django\db\models\manager.py", line 85, in manager_method
    return getattr(self.get_queryset(), name)(*args, **kwargs)
  File "C:\Users\YOGA\AppData\Local\Programs\Python\Python39\lib\site-packages\django\db\models\query.py", line 1270, in _insert
    return query.get_compiler(using=using).execute_sql(returning_fields)
  File "C:\Users\YOGA\AppData\Local\Programs\Python\Python39\lib\site-packages\django\db\models\sql\compiler.py", line 1416, in execute_sql
    cursor.execute(sql, params)
  File "C:\Users\YOGA\AppData\Local\Programs\Python\Python39\lib\site-packages\django\db\backends\utils.py", line 98, in execute
    return super().execute(sql, params)
  File "C:\Users\YOGA\AppData\Local\Programs\Python\Python39\lib\site-packages\django\db\backends\utils.py", line 66, in execute
    return self._execute_with_wrappers(sql, params, many=False, executor=self._execute)
  File "C:\Users\YOGA\AppData\Local\Programs\Python\Python39\lib\site-packages\django\db\backends\utils.py", line 75, in _execute_with_wrappers
    return executor(sql, params, many, context)
  File "C:\Users\YOGA\AppData\Local\Programs\Python\Python39\lib\site-packages\django\db\backends\utils.py", line 84, in _execute
    return self.cursor.execute(sql, params)
  File "C:\Users\YOGA\AppData\Local\Programs\Python\Python39\lib\site-packages\django\db\utils.py", line 90, in __exit__
    raise dj_exc_value.with_traceback(traceback) from exc_value
  File "C:\Users\YOGA\AppData\Local\Programs\Python\Python39\lib\site-packages\django\db\backends\utils.py", line 84, in _execute
    return self.cursor.execute(sql, params)
  File "C:\Users\YOGA\AppData\Local\Programs\Python\Python39\lib\site-packages\django\db\backends\sqlite3\base.py", line 423, in execute
    return Database.Cursor.execute(self, query, params)
django.db.utils.IntegrityError: NOT NULL constraint failed: internal_tablemodel.username
2021-07-22 18:08:58,842 django.request ERROR    Internal Server Error: /internal/create/
Traceback (most recent call last):
  File "C:\Users\YOGA\AppData\Local\Programs\Python\Python39\lib\site-packages\django\db\backends\utils.py", line 84, in _execute
    return self.cursor.execute(sql, params)
  File "C:\Users\YOGA\AppData\Local\Programs\Python\Python39\lib\site-packages\django\db\backends\sqlite3\base.py", line 423, in execute
    return Database.Cursor.execute(self, query, params)
sqlite3.IntegrityError: NOT NULL constraint failed: internal_tablemodel.username

The above exception was the direct cause of the following exception:

Traceback (most recent call last):
  File "C:\Users\YOGA\AppData\Local\Programs\Python\Python39\lib\site-packages\django\core\handlers\exception.py", line 47, in inner
    response = get_response(request)
  File "C:\Users\YOGA\AppData\Local\Programs\Python\Python39\lib\site-packages\django\core\handlers\base.py", line 181, in _get_response
    response = wrapped_callback(request, *callback_args, **callback_kwargs)
  File "C:\Users\YOGA\Documents\richasdy\xd\internal\views.py", line 122, in create
    TableModel.objects.create(
  File "C:\Users\YOGA\AppData\Local\Programs\Python\Python39\lib\site-packages\django\db\models\manager.py", line 85, in manager_method
    return getattr(self.get_queryset(), name)(*args, **kwargs)
  File "C:\Users\YOGA\AppData\Local\Programs\Python\Python39\lib\site-packages\django\db\models\query.py", line 453, in create
    obj.save(force_insert=True, using=self.db)
  File "C:\Users\YOGA\AppData\Local\Programs\Python\Python39\lib\site-packages\django\db\models\base.py", line 726, in save
    self.save_base(using=using, force_insert=force_insert,
  File "C:\Users\YOGA\AppData\Local\Programs\Python\Python39\lib\site-packages\django\db\models\base.py", line 763, in save_base
    updated = self._save_table(
  File "C:\Users\YOGA\AppData\Local\Programs\Python\Python39\lib\site-packages\django\db\models\base.py", line 868, in _save_table
    results = self._do_insert(cls._base_manager, using, fields, returning_fields, raw)
  File "C:\Users\YOGA\AppData\Local\Programs\Python\Python39\lib\site-packages\django\db\models\base.py", line 906, in _do_insert
    return manager._insert(
  File "C:\Users\YOGA\AppData\Local\Programs\Python\Python39\lib\site-packages\django\db\models\manager.py", line 85, in manager_method
    return getattr(self.get_queryset(), name)(*args, **kwargs)
  File "C:\Users\YOGA\AppData\Local\Programs\Python\Python39\lib\site-packages\django\db\models\query.py", line 1270, in _insert
    return query.get_compiler(using=using).execute_sql(returning_fields)
  File "C:\Users\YOGA\AppData\Local\Programs\Python\Python39\lib\site-packages\django\db\models\sql\compiler.py", line 1416, in execute_sql
    cursor.execute(sql, params)
  File "C:\Users\YOGA\AppData\Local\Programs\Python\Python39\lib\site-packages\django\db\backends\utils.py", line 98, in execute
    return super().execute(sql, params)
  File "C:\Users\YOGA\AppData\Local\Programs\Python\Python39\lib\site-packages\django\db\backends\utils.py", line 66, in execute
    return self._execute_with_wrappers(sql, params, many=False, executor=self._execute)
  File "C:\Users\YOGA\AppData\Local\Programs\Python\Python39\lib\site-packages\django\db\backends\utils.py", line 75, in _execute_with_wrappers
    return executor(sql, params, many, context)
  File "C:\Users\YOGA\AppData\Local\Programs\Python\Python39\lib\site-packages\django\db\backends\utils.py", line 84, in _execute
    return self.cursor.execute(sql, params)
  File "C:\Users\YOGA\AppData\Local\Programs\Python\Python39\lib\site-packages\django\db\utils.py", line 90, in __exit__
    raise dj_exc_value.with_traceback(traceback) from exc_value
  File "C:\Users\YOGA\AppData\Local\Programs\Python\Python39\lib\site-packages\django\db\backends\utils.py", line 84, in _execute
    return self.cursor.execute(sql, params)
  File "C:\Users\YOGA\AppData\Local\Programs\Python\Python39\lib\site-packages\django\db\backends\sqlite3\base.py", line 423, in execute
    return Database.Cursor.execute(self, query, params)
django.db.utils.IntegrityError: NOT NULL constraint failed: internal_tablemodel.username
2021-07-22 18:10:09,582 django.request ERROR    Internal Server Error: /internal/create/
Traceback (most recent call last):
  File "C:\Users\YOGA\AppData\Local\Programs\Python\Python39\lib\site-packages\django\db\backends\utils.py", line 84, in _execute
    return self.cursor.execute(sql, params)
  File "C:\Users\YOGA\AppData\Local\Programs\Python\Python39\lib\site-packages\django\db\backends\sqlite3\base.py", line 423, in execute
    return Database.Cursor.execute(self, query, params)
sqlite3.IntegrityError: NOT NULL constraint failed: internal_tablemodel.username

The above exception was the direct cause of the following exception:

Traceback (most recent call last):
  File "C:\Users\YOGA\AppData\Local\Programs\Python\Python39\lib\site-packages\django\core\handlers\exception.py", line 47, in inner
    response = get_response(request)
  File "C:\Users\YOGA\AppData\Local\Programs\Python\Python39\lib\site-packages\django\core\handlers\base.py", line 181, in _get_response
    response = wrapped_callback(request, *callback_args, **callback_kwargs)
  File "C:\Users\YOGA\Documents\richasdy\xd\internal\views.py", line 122, in create
    TableModel.objects.create(
  File "C:\Users\YOGA\AppData\Local\Programs\Python\Python39\lib\site-packages\django\db\models\manager.py", line 85, in manager_method
    return getattr(self.get_queryset(), name)(*args, **kwargs)
  File "C:\Users\YOGA\AppData\Local\Programs\Python\Python39\lib\site-packages\django\db\models\query.py", line 453, in create
    obj.save(force_insert=True, using=self.db)
  File "C:\Users\YOGA\AppData\Local\Programs\Python\Python39\lib\site-packages\django\db\models\base.py", line 726, in save
    self.save_base(using=using, force_insert=force_insert,
  File "C:\Users\YOGA\AppData\Local\Programs\Python\Python39\lib\site-packages\django\db\models\base.py", line 763, in save_base
    updated = self._save_table(
  File "C:\Users\YOGA\AppData\Local\Programs\Python\Python39\lib\site-packages\django\db\models\base.py", line 868, in _save_table
    results = self._do_insert(cls._base_manager, using, fields, returning_fields, raw)
  File "C:\Users\YOGA\AppData\Local\Programs\Python\Python39\lib\site-packages\django\db\models\base.py", line 906, in _do_insert
    return manager._insert(
  File "C:\Users\YOGA\AppData\Local\Programs\Python\Python39\lib\site-packages\django\db\models\manager.py", line 85, in manager_method
    return getattr(self.get_queryset(), name)(*args, **kwargs)
  File "C:\Users\YOGA\AppData\Local\Programs\Python\Python39\lib\site-packages\django\db\models\query.py", line 1270, in _insert
    return query.get_compiler(using=using).execute_sql(returning_fields)
  File "C:\Users\YOGA\AppData\Local\Programs\Python\Python39\lib\site-packages\django\db\models\sql\compiler.py", line 1416, in execute_sql
    cursor.execute(sql, params)
  File "C:\Users\YOGA\AppData\Local\Programs\Python\Python39\lib\site-packages\django\db\backends\utils.py", line 98, in execute
    return super().execute(sql, params)
  File "C:\Users\YOGA\AppData\Local\Programs\Python\Python39\lib\site-packages\django\db\backends\utils.py", line 66, in execute
    return self._execute_with_wrappers(sql, params, many=False, executor=self._execute)
  File "C:\Users\YOGA\AppData\Local\Programs\Python\Python39\lib\site-packages\django\db\backends\utils.py", line 75, in _execute_with_wrappers
    return executor(sql, params, many, context)
  File "C:\Users\YOGA\AppData\Local\Programs\Python\Python39\lib\site-packages\django\db\backends\utils.py", line 84, in _execute
    return self.cursor.execute(sql, params)
  File "C:\Users\YOGA\AppData\Local\Programs\Python\Python39\lib\site-packages\django\db\utils.py", line 90, in __exit__
    raise dj_exc_value.with_traceback(traceback) from exc_value
  File "C:\Users\YOGA\AppData\Local\Programs\Python\Python39\lib\site-packages\django\db\backends\utils.py", line 84, in _execute
    return self.cursor.execute(sql, params)
  File "C:\Users\YOGA\AppData\Local\Programs\Python\Python39\lib\site-packages\django\db\backends\sqlite3\base.py", line 423, in execute
    return Database.Cursor.execute(self, query, params)
django.db.utils.IntegrityError: NOT NULL constraint failed: internal_tablemodel.username
2021-07-22 20:26:03,568 django.utils.autoreload INFO     C:\Users\YOGA\Documents\richasdy\xd\external\views.py changed, reloading.
2021-07-22 20:26:15,278 django.utils.autoreload INFO     Watching for file changes with StatReloader
2021-07-22 20:33:22,134 external.views INFO     loading portal berita view
2021-07-22 20:34:01,982 external.views INFO     loading portal berita view
2021-07-22 20:37:33,189 django.utils.autoreload INFO     C:\Users\YOGA\Documents\richasdy\xd\external\views.py changed, reloading.
2021-07-22 20:37:34,446 django.utils.autoreload INFO     Watching for file changes with StatReloader
2021-07-22 20:38:37,737 external.views INFO     loading Portal view
2021-07-22 20:40:35,210 external.views INFO     loading twitter view
2021-07-22 20:45:45,876 external.views INFO     loading Portal view
2021-07-23 03:58:17,641 django.utils.autoreload INFO     Watching for file changes with StatReloader
2021-07-23 03:58:26,541 django.request WARNING  Not Found: /
2021-07-23 03:58:26,887 django.request WARNING  Not Found: /favicon.ico
2021-07-23 03:58:40,438 django.request WARNING  Not Found: /stakeholder
2021-07-23 03:58:43,077 django.request WARNING  Not Found: /stakeholder/
2021-07-23 03:58:47,245 django.request ERROR    Internal Server Error: /stakeholder/alumni
Traceback (most recent call last):
  File "C:\Users\My ASUS\Documents\GitHub\env\lib\site-packages\django\core\handlers\exception.py", line 47, in inner
    response = get_response(request)
  File "C:\Users\My ASUS\Documents\GitHub\env\lib\site-packages\django\core\handlers\base.py", line 181, in _get_response
    response = wrapped_callback(request, *callback_args, **callback_kwargs)
  File "C:\Users\My ASUS\Documents\GitHub\xd\stakeholder\views.py", line 5, in alumni
    return render(request, "alumni.html")
  File "C:\Users\My ASUS\Documents\GitHub\env\lib\site-packages\django\shortcuts.py", line 19, in render
    content = loader.render_to_string(template_name, context, request, using=using)
  File "C:\Users\My ASUS\Documents\GitHub\env\lib\site-packages\django\template\loader.py", line 61, in render_to_string
    template = get_template(template_name, using=using)
  File "C:\Users\My ASUS\Documents\GitHub\env\lib\site-packages\django\template\loader.py", line 19, in get_template
    raise TemplateDoesNotExist(template_name, chain=chain)
django.template.exceptions.TemplateDoesNotExist: alumni.html
2021-07-23 03:59:15,149 django.utils.autoreload INFO     C:\Users\My ASUS\Documents\GitHub\xd\stakeholder\views.py changed, reloading.
2021-07-23 03:59:17,072 django.utils.autoreload INFO     Watching for file changes with StatReloader
2021-07-23 04:15:53,571 django.utils.autoreload INFO     Watching for file changes with StatReloader
2021-07-23 04:17:22,395 django.request WARNING  Not Found: /stakeholder/
2021-07-23 04:17:41,651 django.request WARNING  Not Found: /
2021-07-23 04:18:20,168 django.utils.autoreload INFO     Watching for file changes with StatReloader
2021-07-23 04:18:20,602 django.request WARNING  Not Found: /
2021-07-23 04:25:11,797 external.views INFO     loading twitter view
2021-07-23 04:41:14,087 external.views INFO     loading instagram view
